<?xml version="1.0"?>
<robot name="/home/jayhuang/programs/ROS2-Project/src/my_create/resource/MyCreate.urdf
" xmlns:xacro="http://ros.org/wiki/xacro">
<!-- <robot name="MyCreate" xmlns:xacro="http://ros.org/wiki/xacro"> -->
  <webots>
    <plugin type="my_create.my_robot_driver.MyRobotDriver"/>
  </webots>
  <link name="base_link">
  </link>
  <link name="camera_left">
  </link>
  <joint name="base_link_camera_left_joint" type="fixed">
    <parent link="base_link"/>
    <child link="camera_left"/>
    <origin xyz="0.14 0.05 0.11" rpy="-1.570796 0 -1.570796"/>
  </joint>
  <link name="camera_right">
  </link>
  <joint name="base_link_camera_right_joint" type="fixed">
    <parent link="base_link"/>
    <child link="camera_right"/>
    <origin xyz="0.14 -0.05 0.11" rpy="-1.570796 0.000005 -1.570796"/>
  </joint>
  <link name="stand_left_back_2">
    <visual>
      <geometry>
        <cylinder radius="0.005" length="0.09"/>
      </geometry>
    </visual>
    <collision>
      <geometry>
        <cylinder radius="0.005" length="0.09"/>
      </geometry>
    </collision>
  </link>
  <joint name="base_link_stand_left_back_2_joint" type="fixed">
    <parent link="base_link"/>
    <child link="stand_left_back_2"/>
    <origin xyz="-0.08 0.106 0.16" rpy="0 0 0"/>
  </joint>
  <link name="stand_left_front_2">
    <visual>
      <geometry>
        <cylinder radius="0.005" length="0.09"/>
      </geometry>
    </visual>
    <collision>
      <geometry>
        <cylinder radius="0.005" length="0.09"/>
      </geometry>
    </collision>
  </link>
  <joint name="base_link_stand_left_front_2_joint" type="fixed">
    <parent link="base_link"/>
    <child link="stand_left_front_2"/>
    <origin xyz="-0.01 0.116 0.16" rpy="0 0 0"/>
  </joint>
  <link name="stand_right_back_2">
    <visual>
      <geometry>
        <cylinder radius="0.005" length="0.09"/>
      </geometry>
    </visual>
    <collision>
      <geometry>
        <cylinder radius="0.005" length="0.09"/>
      </geometry>
    </collision>
  </link>
  <joint name="base_link_stand_right_back_2_joint" type="fixed">
    <parent link="base_link"/>
    <child link="stand_right_back_2"/>
    <origin xyz="-0.08 -0.106 0.16" rpy="0 0 0"/>
  </joint>
  <link name="stand_right_front_2">
    <visual>
      <geometry>
        <cylinder radius="0.005" length="0.09"/>
      </geometry>
    </visual>
    <collision>
      <geometry>
        <cylinder radius="0.005" length="0.09"/>
      </geometry>
    </collision>
  </link>
  <joint name="base_link_stand_right_front_2_joint" type="fixed">
    <parent link="base_link"/>
    <child link="stand_right_front_2"/>
    <origin xyz="-0.01 -0.12 0.16" rpy="0 0 0"/>
  </joint>
  <link name="stand_left_back_1">
    <visual>
      <geometry>
        <cylinder radius="0.005" length="0.07"/>
      </geometry>
    </visual>
    <collision>
      <geometry>
        <cylinder radius="0.005" length="0.07"/>
      </geometry>
    </collision>
  </link>
  <joint name="base_link_stand_left_back_1_joint" type="fixed">
    <parent link="base_link"/>
    <child link="stand_left_back_1"/>
    <origin xyz="-0.08 0.106 0.07" rpy="0 0 0"/>
  </joint>
  <link name="stand_left_front_1">
    <visual>
      <geometry>
        <cylinder radius="0.005" length="0.07"/>
      </geometry>
    </visual>
    <collision>
      <geometry>
        <cylinder radius="0.005" length="0.07"/>
      </geometry>
    </collision>
  </link>
  <joint name="base_link_stand_left_front_1_joint" type="fixed">
    <parent link="base_link"/>
    <child link="stand_left_front_1"/>
    <origin xyz="-0.01 0.116 0.07" rpy="0 0 0"/>
  </joint>
  <link name="stand_right_back_1">
    <visual>
      <geometry>
        <cylinder radius="0.005" length="0.07"/>
      </geometry>
    </visual>
    <collision>
      <geometry>
        <cylinder radius="0.005" length="0.07"/>
      </geometry>
    </collision>
  </link>
  <joint name="base_link_stand_right_back_1_joint" type="fixed">
    <parent link="base_link"/>
    <child link="stand_right_back_1"/>
    <origin xyz="-0.08 -0.106 0.07" rpy="0 0 0"/>
  </joint>
  <link name="stand_right_front_1">
    <visual>
      <geometry>
        <cylinder radius="0.005" length="0.07"/>
      </geometry>
    </visual>
    <collision>
      <geometry>
        <cylinder radius="0.005" length="0.07"/>
      </geometry>
    </collision>
  </link>
  <joint name="base_link_stand_right_front_1_joint" type="fixed">
    <parent link="base_link"/>
    <child link="stand_right_front_1"/>
    <origin xyz="-0.01 -0.12 0.07" rpy="0 0 0"/>
  </joint>
  <link name="plate_2">
  </link>
  <joint name="base_link_plate_2_joint" type="fixed">
    <parent link="base_link"/>
    <child link="plate_2"/>
    <origin xyz="0 0 0.205" rpy="0 0 0"/>
  </joint>
  <link name="plate_1">
  </link>
  <joint name="base_link_plate_1_joint" type="fixed">
    <parent link="base_link"/>
    <child link="plate_1"/>
    <origin xyz="0 0 0.11" rpy="0 0 0"/>
  </joint>
  <link name="cliff_left">
  </link>
  <joint name="base_link_cliff_left_joint" type="fixed">
    <parent link="base_link"/>
    <child link="cliff_left"/>
    <origin xyz="0.07 0.15 0" rpy="-1.876967 1.570787 1.264616"/>
  </joint>
  <link name="cliff_front_left">
  </link>
  <joint name="base_link_cliff_front_left_joint" type="fixed">
    <parent link="base_link"/>
    <child link="cliff_front_left"/>
    <origin xyz="0.15 0.04 0" rpy="-1.876967 1.570787 1.264616"/>
  </joint>
  <link name="cliff_front_right">
  </link>
  <joint name="base_link_cliff_front_right_joint" type="fixed">
    <parent link="base_link"/>
    <child link="cliff_front_right"/>
    <origin xyz="0.15 -0.04 0" rpy="-1.876967 1.570787 1.264616"/>
  </joint>
  <link name="cliff_right">
  </link>
  <joint name="base_link_cliff_right_joint" type="fixed">
    <parent link="base_link"/>
    <child link="cliff_right"/>
    <origin xyz="0.07 -0.15 0" rpy="-1.876967 1.570787 1.264616"/>
  </joint>
  <link name="led_step">
  </link>
  <joint name="base_link_led_step_joint" type="fixed">
    <parent link="base_link"/>
    <child link="led_step"/>
    <origin xyz="0.0189 -0.0581 0.0349" rpy="0 0 0"/>
  </joint>
  <link name="led_play">
  </link>
  <joint name="base_link_led_play_joint" type="fixed">
    <parent link="base_link"/>
    <child link="led_play"/>
    <origin xyz="0.0193 -0.0132 0.0349" rpy="0 0 0"/>
  </joint>
  <link name="led_on">
  </link>
  <joint name="base_link_led_on_joint" type="fixed">
    <parent link="base_link"/>
    <child link="led_on"/>
    <origin xyz="0.0202 0.0617 0.0349" rpy="0 0 0"/>
  </joint>
  <link name="bumper_right">
    <visual>
      <origin xyz="-0.078042 0 -0.148208" rpy="0 0.523599 0"/>
      <geometry>
        <box size="0.082811 0.07 0.01"/>
      </geometry>
    </visual>
    <collision>
      <origin xyz="-0.078042 0 -0.148208" rpy="0 0.523599 0"/>
      <geometry>
        <box size="0.082811 0.07 0.01"/>
      </geometry>
    </collision>
    <visual>
      <origin xyz="0 0 -0.1675" rpy="0 0 0"/>
      <geometry>
        <box size="0.082811 0.07 0.01"/>
      </geometry>
    </visual>
    <collision>
      <origin xyz="0 0 -0.1675" rpy="0 0 0"/>
      <geometry>
        <box size="0.082811 0.07 0.01"/>
      </geometry>
    </collision>
    <visual>
      <origin xyz="0.078042 0 -0.148208" rpy="0 -0.523599 0"/>
      <geometry>
        <box size="0.082811 0.07 0.01"/>
      </geometry>
    </visual>
    <collision>
      <origin xyz="0.078042 0 -0.148208" rpy="0 -0.523599 0"/>
      <geometry>
        <box size="0.082811 0.07 0.01"/>
      </geometry>
    </collision>
  </link>
  <joint name="base_link_bumper_right_joint" type="fixed">
    <parent link="base_link"/>
    <child link="bumper_right"/>
    <origin xyz="0 0 0" rpy="1.570792 0.000011 -2.297729"/>
  </joint>
  <link name="bumper_left">
    <visual>
      <origin xyz="-0.078042 0 -0.148208" rpy="0 0.523599 0"/>
      <geometry>
        <box size="0.082811 0.07 0.01"/>
      </geometry>
    </visual>
    <collision>
      <origin xyz="-0.078042 0 -0.148208" rpy="0 0.523599 0"/>
      <geometry>
        <box size="0.082811 0.07 0.01"/>
      </geometry>
    </collision>
    <visual>
      <origin xyz="0 0 -0.1675" rpy="0 0 0"/>
      <geometry>
        <box size="0.082811 0.07 0.01"/>
      </geometry>
    </visual>
    <collision>
      <origin xyz="0 0 -0.1675" rpy="0 0 0"/>
      <geometry>
        <box size="0.082811 0.07 0.01"/>
      </geometry>
    </collision>
    <visual>
      <origin xyz="0.078042 0 -0.148208" rpy="0 -0.523599 0"/>
      <geometry>
        <box size="0.082811 0.07 0.01"/>
      </geometry>
    </visual>
    <collision>
      <origin xyz="0.078042 0 -0.148208" rpy="0 -0.523599 0"/>
      <geometry>
        <box size="0.082811 0.07 0.01"/>
      </geometry>
    </collision>
  </link>
  <joint name="base_link_bumper_left_joint" type="fixed">
    <parent link="base_link"/>
    <child link="bumper_left"/>
    <origin xyz="0 0 0" rpy="1.570806 0.000006 -0.843867"/>
  </joint>
  <link name="receiver">
  </link>
  <joint name="base_link_receiver_joint" type="fixed">
    <parent link="base_link"/>
    <child link="receiver"/>
    <origin xyz="0.152 0 0.037" rpy="0 0 0"/>
  </joint>
  <link name="front wheel">
  </link>
  <joint name="base_link_front wheel_joint" type="fixed">
    <parent link="base_link"/>
    <child link="front wheel"/>
    <origin xyz="0.129 0 -0.035" rpy="0 0 0"/>
  </joint>
  <link name="rear wheel">
  </link>
  <joint name="base_link_rear wheel_joint" type="fixed">
    <parent link="base_link"/>
    <child link="rear wheel"/>
    <origin xyz="-0.1315 0 -0.0305" rpy="0 0 0"/>
  </joint>
  <joint name="left wheel motor" type="continuous">
    <parent link="base_link"/>
    <child link="left wheel"/>
    <axis xyz="0 1 0"/>
    <limit effort="10" velocity="16.129"/>
    <origin xyz="-0.0062 0 -0.014" rpy="0 0 0"/>
  </joint>
  <link name="left wheel">
    <visual>
      <origin xyz="0 0.1359 0" rpy="1.5708 0 0"/>
      <geometry>
        <cylinder radius="0.031" length="0.026"/>
      </geometry>
    </visual>
    <collision>
      <origin xyz="0 0.1359 0" rpy="1.5708 0 0"/>
      <geometry>
        <cylinder radius="0.031" length="0.026"/>
      </geometry>
    </collision>
  </link>
  <joint name="right wheel motor" type="continuous">
    <parent link="base_link"/>
    <child link="right wheel"/>
    <axis xyz="0 1 0"/>
    <limit effort="10" velocity="16.129"/>
    <origin xyz="-0.0062 0.1359 -0.014" rpy="0 0 0"/>
  </joint>
  <link name="right wheel">
    <visual>
      <origin xyz="0 -0.1359 0" rpy="1.5708 0 0"/>
      <geometry>
        <cylinder radius="0.031" length="0.026"/>
      </geometry>
    </visual>
    <collision>
      <origin xyz="0 -0.1359 0" rpy="1.5708 0 0"/>
      <geometry>
        <cylinder radius="0.031" length="0.026"/>
      </geometry>
    </collision>
  </link>
</robot>
