<?xml version="1.0"?>
<robot name="/home/jordenhuang/webots_ros2/src/my_package/resource/TurtleBot3Waffle.urdf" xmlns:xacro="http://ros.org/wiki/xacro">
  <webots>
    <plugin type="my_package.my_robot_driver.MyRobotDriver" />
  </webots>
  <link name="base_link">
    <visual>
      <origin xyz="-0.095 -0.064 0.065" rpy="0 0 0"/>
      <geometry>
        <box size="0.226 0.267 0.1"/>
      </geometry>
    </visual>
    <collision>
      <origin xyz="-0.095 -0.064 0.065" rpy="0 0 0"/>
      <geometry>
        <box size="0.226 0.267 0.1"/>
      </geometry>
    </collision>
    <visual>
      <origin xyz="-0.096 -0.064 0.06" rpy="0 0 0"/>
      <geometry>
        <box size="0.265 0.215 0.1"/>
      </geometry>
    </visual>
    <collision>
      <origin xyz="-0.096 -0.064 0.06" rpy="0 0 0"/>
      <geometry>
        <box size="0.265 0.215 0.1"/>
      </geometry>
    </collision>
  </link>
  <link name="emitter">
  </link>
  <joint name="base_link_emitter_joint" type="fixed">
    <parent link="base_link"/>
    <child link="emitter"/>
    <origin xyz="0 0 0" rpy="0 0 0"/>
  </joint>
  <link name="receiver">
  </link>
  <joint name="base_link_receiver_joint" type="fixed">
    <parent link="base_link"/>
    <child link="receiver"/>
    <origin xyz="0 0 0" rpy="0 0 0"/>
  </joint>
  <link name="camera_right">
  </link>
  <joint name="base_link_camera_right_joint" type="fixed">
    <parent link="base_link"/>
    <child link="camera_right"/>
    <origin xyz="-0.225 -0.093 0.05" rpy="-1.570796 0 1.569204"/>
  </joint>
  <link name="camera_left">
  </link>
  <joint name="base_link_camera_left_joint" type="fixed">
    <parent link="base_link"/>
    <child link="camera_left"/>
    <origin xyz="-0.225 -0.035 0.05" rpy="-1.570796 0 1.569204"/>
  </joint>
  <link name="compass">
  </link>
  <joint name="base_link_compass_joint" type="fixed">
    <parent link="base_link"/>
    <child link="compass"/>
    <origin xyz="-0.032 0 0.078" rpy="0 0 0"/>
  </joint>
  <link name="gyro">
  </link>
  <joint name="base_link_gyro_joint" type="fixed">
    <parent link="base_link"/>
    <child link="gyro"/>
    <origin xyz="-0.032 0 0.078" rpy="0 0 0"/>
  </joint>
  <link name="accelerometer">
  </link>
  <joint name="base_link_accelerometer_joint" type="fixed">
    <parent link="base_link"/>
    <child link="accelerometer"/>
    <origin xyz="-0.032 0 0.078" rpy="0 0 0"/>
  </joint>
  <joint name="left_wheel_motor" type="continuous">
    <parent link="base_link"/>
    <child link="left_wheel"/>
    <axis xyz="-0.000003 -1 0.000003"/>
    <limit effort="10" velocity="6.67"/>
    <origin xyz="0 0.08 0.033" rpy="-0.527129 -1.57079 -2.614461"/>
  </joint>
  <link name="left_wheel">
    <visual>
      <origin xyz="0.000033 0 0.000001" rpy="-1.570796 0 0"/>
      <geometry>
        <cylinder radius="0.033" length="0.018"/>
      </geometry>
    </visual>
    <collision>
      <origin xyz="0.000033 0 0.000001" rpy="-1.570796 0 0"/>
      <geometry>
        <cylinder radius="0.033" length="0.018"/>
      </geometry>
    </collision>
  </link>
  <joint name="right_wheel_motor" type="continuous">
    <parent link="base_link"/>
    <child link="right_wheel"/>
    <axis xyz="0.000002 1 0"/>
    <limit effort="10" velocity="6.67"/>
    <origin xyz="0.000033 -0.08 0.033001" rpy="-1.370641 -1.570794 1.370641"/>
  </joint>
  <link name="right_wheel">
    <visual>
      <origin xyz="0.000014 -0.13 -0.000001" rpy="-1.570796 0 0"/>
      <geometry>
        <cylinder radius="0.033" length="0.018"/>
      </geometry>
    </visual>
    <collision>
      <origin xyz="0.000014 -0.13 -0.000001" rpy="-1.570796 0 0"/>
      <geometry>
        <cylinder radius="0.033" length="0.018"/>
      </geometry>
    </collision>
  </link>
</robot>
