#VRML_SIM R2023b utf8

PROTO TurtleBot3Waffle [
  field  SFVec3f     translation          0 0 0
  field  SFRotation  rotation             0 0 1 0
  field  SFString    name                 "TurtleBot"  # Is `Robot.name`.
  field  SFString    controller           "<none>"     # Is `Robot.controller`.
  field  MFString    controllerArgs       []           # Is `Robot.controllerArgs`.
  field SFString     window               ""           # Is `Robot.window`.
  field  SFString    customData           ""           # Is `Robot.customData`.
  field  SFBool      supervisor           FALSE        # Is `Robot.supervisor`.
  field  SFBool      synchronization      TRUE         # Is `Robot.synchronization`.
  field SFFloat      camera_fieldOfView   0.84         # Is `Camera.fieldOfView`.
  field SFInt32      camera_width         192           # Is `Camera.width`.
  field SFInt32      camera_height        96           # Is `Camera.height`.
  field SFBool       camera_antiAliasing  FALSE        # Is `Camera.antiAliasing`.
  field SFRotation   camera_rotation      0 0 1 3.14      # Is `Camera.rotation`. Interesting setup: set `0 1 0 0.47` in order to simulate the linear camera mode.
  field SFFloat      camera_noise         0.0          # Is `Camera.noise`.
  field SFFloat      camera_motionBlur    0.0          # Is `Camera.motionBlur`.
  field SFInt32      emitter_channel      1            # Is `Emitter.channel`.
  field SFInt32      receiver_channel     1            # Is `Receiver.channel`.
  field  SFBool      selfCollision        FALSE        # Is `Robot.selfCollision`.
  field  MFNode      arm_slot             []           # Put the arm here
]

{
  Robot {
    translation IS translation
    rotation IS rotation
    controller IS controller
    controllerArgs IS controllerArgs
    window IS window
    customData IS customData
    supervisor IS supervisor
    synchronization IS synchronization
    selfCollision IS selfCollision
    children [
      DEF RIGHT_JOINT HingeJoint {
        jointParameters HingeJointParameters {
          position 2.672190152695405e-07
          axis 0 1 0
          anchor 0 -0.08 0.033
        }
        device [
          RotationalMotor {
            name "right_wheel_motor"
            consumptionFactor -0.001
            maxVelocity 6.67
          }
          PositionSensor {
            name "right_wheel_sensor"
            resolution 0.00628
          }
        ]
        endPoint Solid {
          translation 6.138182796633751e-07 -0.20999999818845277 0.03301426927114876
          rotation -8.701609480565146e-07 -0.9999999999991718 9.483869074014775e-07 1.5707959578641377
          children [
            DEF RIGHT_WHEEL Pose {
              rotation 1 0 0 -1.5708003061004252
              children [
                DEF WHEEL_SHAPE Group {
                  children [
                    Shape {
                      appearance PBRAppearance {
                        baseColor 0 0 0
                        roughness 1
                        metalness 0
                      }
                      geometry Mesh {
                        url [
                          "./turtleBot3Waffle_mesh/wheel_shape.obj"
                        ]
                      }
                    }
                    Shape {
                      appearance PBRAppearance {
                        baseColor 0 0 0
                        roughness 1
                        metalness 0
                      }
                      geometry Mesh {
                        url [
                          "./turtleBot3Waffle_mesh/inner_wheel.obj"
                        ]
                      }
                    }
                    Shape {
                      appearance PBRAppearance {
                        baseColorMap ImageTexture {
                          url [
                            "https://raw.githubusercontent.com/cyberbotics/webots/R2023b/projects/appearances/protos/textures/tire_rubber/bike_tire_rubber_base_color.jpg"
                          ]
                        }
                        roughnessMap ImageTexture {
                          url [
                            "https://raw.githubusercontent.com/cyberbotics/webots/R2023b/projects/appearances/protos/textures/tire_rubber/bike_tire_rubber_roughness.jpg"
                          ]
                        }
                        metalness 0
                        normalMap ImageTexture {
                          url [
                            "https://raw.githubusercontent.com/cyberbotics/webots/R2023b/projects/appearances/protos/textures/tire_rubber/bike_tire_rubber_normal.jpg"
                          ]
                        }
                        normalMapFactor 8
                        occlusionMap ImageTexture {
                          url [
                            "https://raw.githubusercontent.com/cyberbotics/webots/R2023b/projects/appearances/protos/textures/tire_rubber/bike_tire_rubber_occlusion.jpg"
                          ]
                        }
                        occlusionMapStrength 8
                        textureTransform TextureTransform {
                          scale 1.7 0.76
                          translation 0 0.164
                        }
                      }
                      geometry Mesh {
                        url [
                          "./turtleBot3Waffle_mesh/tire.obj"
                        ]
                      }
                    }
                    Shape {
                      appearance PBRAppearance {
                      }
                      geometry Mesh {
                        url [
                          "./turtleBot3Waffle_mesh/wheel_support.obj"
                        ]
                      }
                    }
                  ]
                }
              ]
            }
          ]
          name "right_wheel"
          boundingObject Pose {
            rotation 1 0 0 -1.570796
            children [
              Cylinder {
                height 0.018
                radius 0.033
              }
            ]
          }
          physics Physics {
            density -1
            mass 0.028499
            centerOfMass [
              0 0 0
            ]
          }
        }
      }
      DEF LEFT_JOINT HingeJoint {
        jointParameters HingeJointParameters {
          position -8.325852876170519e-10
          axis 0 1 0
          anchor 0 0.08 0.033
        }
        device [
          RotationalMotor {
            name "left_wheel_motor"
            consumptionFactor -0.001
            maxVelocity 6.67
          }
          PositionSensor {
            name "left_wheel_sensor"
            resolution 0.00628
          }
        ]
        endPoint Solid {
          translation 1.440984656713383e-06 0.07999997058268785 0.03303340044759471
          rotation -0.7071047796192058 1.7246589396419056e-09 -0.7071087827482239 3.1415879968455727
          children [
            DEF RIGHT_WHEEL Pose {
              rotation 1 0 0 -1.5708003061004252
              children [
                USE WHEEL_SHAPE
              ]
            }
          ]
          name "left_wheel"
          boundingObject Pose {
            rotation 1 0 0 -1.570796
            children [
              Cylinder {
                height 0.018
                radius 0.033
              }
            ]
          }
          physics Physics {
            density -1
            mass 0.028499
            centerOfMass [
              0 0 0
            ]
          }
        }
      }
      DEF CASTER_JOINT_LEFT BallJoint {
        jointParameters BallJointParameters {
          position 1.0373219647942933e-06
          anchor -0.209 0 0.004
        }
        endPoint Solid {
          translation -0.20899999999999996 -4.5850999999999936e-07 0.00402834
          rotation -0.4625644366674983 0.8864690380745265 0.01438007182539337 0.0002461346924332989
          children [
            Shape {
              appearance PBRAppearance {
              }
              geometry DEF CASTER_SPHERE Sphere {
                radius 0.004
                subdivision 2
              }
            }
          ]
          boundingObject USE CASTER_SPHERE
          physics Physics {
          }
        }
      }
      DEF CASTER_JOINT_RIGHT BallJoint {
        jointParameters BallJointParameters {
          position 1.0373219647942933e-06
          anchor -0.209 -0.128 0.004
        }
        endPoint Solid {
          translation -0.209 -0.1279999999999999 0.00404316
          rotation -0.4625644366674983 0.8864690380745265 0.01438007182539337 0.0002461346924332989
          children [
            Shape {
              appearance PBRAppearance {
              }
              geometry USE CASTER_SPHERE
            }
          ]
          name "solid(1)"
          boundingObject USE CASTER_SPHERE
          physics Physics {
          }
        }
      }
      DEF BODY Pose {
        translation 0 0 0.01
        children [
          DEF GROUP_MOTOR Group {
            children [
              DEF MOTOR_POS Pose {
                translation 0 -0.1288 0
                children [
                  DEF MOTORS Shape {
                    appearance PBRAppearance {
                      baseColor 0 0 0
                      roughness 0.8
                      metalness 0
                    }
                    geometry Mesh {
                      url [
                        "./turtleBot3Waffle_mesh/wheel_support.obj"
                      ]
                    }
                  }
                ]
              }
            ]
          }
          DEF CARDS Shape {
            appearance PBRAppearance {
              baseColorMap ImageTexture {
                url [
                  "https://raw.githubusercontent.com/cyberbotics/webots/R2023b/projects/appearances/protos/textures/pcb/pcb_base_color.jpg"
                ]
              }
              roughnessMap ImageTexture {
                url [
                  "https://raw.githubusercontent.com/cyberbotics/webots/R2023b/projects/appearances/protos/textures/pcb/pcb_roughness.jpg"
                ]
              }
              metalnessMap ImageTexture {
                url [
                  "https://raw.githubusercontent.com/cyberbotics/webots/R2023b/projects/appearances/protos/textures/pcb/pcb_metalness.jpg"
                ]
              }
              normalMap ImageTexture {
                url [
                  "https://raw.githubusercontent.com/cyberbotics/webots/R2023b/projects/appearances/protos/textures/pcb/pcb_normal.jpg"
                ]
              }
              normalMapFactor 3
              occlusionMap ImageTexture {
                url [
                  "https://raw.githubusercontent.com/cyberbotics/webots/R2023b/projects/appearances/protos/textures/pcb/pcb_occlusion.jpg"
                ]
              }
              occlusionMapStrength 3
            }
            geometry Mesh {
              url [
                "./turtleBot3Waffle_mesh/cards.obj"
              ]
            }
          }
          DEF GROUP_HOLDERS Group {
            children [
              DEF LEFT_HOLDERS Pose {
                translation -0.128 0 0
                children [
                  DEF HOLDERS Shape {
                    appearance DEF MAIN_APP PBRAppearance {
                      baseColor 0 0 0
                      roughnessMap ImageTexture {
                        url [
                          "https://raw.githubusercontent.com/cyberbotics/webots/R2023b/projects/appearances/protos/textures/rough_polymer/rough_polymer_roughness.jpg"
                        ]
                      }
                      metalness 0
                      normalMap ImageTexture {
                        url [
                          "https://raw.githubusercontent.com/cyberbotics/webots/R2023b/projects/appearances/protos/textures/rough_polymer/rough_polymer_normal.jpg"
                        ]
                      }
                      normalMapFactor 2
                      occlusionMap ImageTexture {
                        url [
                          "https://raw.githubusercontent.com/cyberbotics/webots/R2023b/projects/appearances/protos/textures/rough_polymer/rough_polymer_occlusion.jpg"
                        ]
                      }
                      occlusionMapStrength 2
                      textureTransform TextureTransform {
                        scale 3 3
                      }
                    }
                    geometry Mesh {
                      url [
                        "./turtleBot3Waffle_mesh/holders.obj"
                      ]
                    }
                  }
                ]
              }
              DEF RIGHT_HOLDERS Pose {
                translation -0.128 -0.128 0
                children [
                  USE HOLDERS
                ]
              }
            ]
          }
          DEF GROUP_FLOOR_0 Group {
            children [
              DEF LEFT_1_FLOOR_0 Pose {
                children [
                  DEF BODY_FLOOR_0 Shape {
                    appearance USE MAIN_APP
                    geometry Mesh {
                      url [
                        "./turtleBot3Waffle_mesh/body_floor.obj"
                      ]
                    }
                  }
                ]
              }
              DEF LEFT_2_FLOOR_0 Pose {
                translation -0.128 0 0
                children [
                  USE BODY_FLOOR_0
                ]
              }
              DEF RIGHT_1_FLOOR_0 Pose {
                translation 0 -0.128 0
                children [
                  USE BODY_FLOOR_0
                ]
              }
              DEF RIGHT_2_FLOOR_0 Pose {
                translation -0.128 -0.128 0
                children [
                  USE BODY_FLOOR_0
                ]
              }
            ]
          }
          DEF GROUP_FLOOR_1 Group {
            children [
              DEF LEFT_1_FLOOR_1 Pose {
                translation 0 0 0.0376
                children [
                  USE BODY_FLOOR_0
                ]
              }
              DEF LEFT_2_FLOOR_1 Pose {
                translation -0.128 0 0.0376
                children [
                  USE BODY_FLOOR_0
                ]
              }
              DEF RIGHT_1_FLOOR_1 Pose {
                translation 0 -0.128 0.0376
                children [
                  USE BODY_FLOOR_0
                ]
              }
              DEF RIGHT_2_FLOOR_1 Pose {
                translation -0.128 -0.128 0.0376
                children [
                  USE BODY_FLOOR_0
                ]
              }
            ]
          }
          DEF GROUP_FLOOR_2 Group {
            children [
              DEF LEFT_1_FLOOR_2 Pose {
                translation 0 0 0.085
                children [
                  USE BODY_FLOOR_0
                ]
              }
              DEF LEFT_2_FLOOR_2 Pose {
                translation -0.128 0 0.085
                children [
                  USE BODY_FLOOR_0
                ]
              }
              DEF RIGHT_1_FLOOR_2 Pose {
                translation 0 -0.128 0.085
                children [
                  USE BODY_FLOOR_0
                ]
              }
              DEF RIGHT_2_FLOOR_2 Pose {
                translation -0.128 -0.128 0.085
                children [
                  USE BODY_FLOOR_0
                ]
              }
            ]
          }
          DEF BATTERY Shape {
            appearance PBRAppearance {
              baseColor 0.054902 0.121569 0.356863
              baseColorMap ImageTexture {
                url [
                  "https://raw.githubusercontent.com/cyberbotics/webots/R2023b/projects/appearances/protos/textures/matte_car_paint/matte_car_paint_base_color.jpg"
                ]
                filtering 5
              }
              roughnessMap ImageTexture {
                url [
                  "https://raw.githubusercontent.com/cyberbotics/webots/R2023b/projects/appearances/protos/textures/matte_car_paint/matte_car_paint_roughness.jpg"
                ]
                filtering 5
              }
              metalness 0
              normalMapFactor 0.5
              textureTransform TextureTransform {
                scale 10 10
              }
            }
            geometry Mesh {
              url [
                "./turtleBot3Waffle_mesh/battery.obj"
              ]
            }
          }
          DEF GROUP_SCREWS Group {
            children [
              DEF LEFT_1_SCREWS Pose {
                children [
                  DEF SCREWS Shape {
                    appearance PBRAppearance {
                    }
                    geometry Mesh {
                      url [
                        "./turtleBot3Waffle_mesh/waffle_screw.obj"
                      ]
                    }
                  }
                ]
              }
              DEF LEFT_2_SCREWS Pose {
                translation -0.128 0 0
                children [
                  USE SCREWS
                ]
              }
              DEF RIGHT_1_SCREWS Pose {
                translation 0 -0.128 0
                children [
                  USE SCREWS
                ]
              }
              DEF RIGHT_2_SCREWS Pose {
                translation -0.128 -0.128 0
                children [
                  USE SCREWS
                ]
              }
            ]
          }
          DEF GROUP_BARS Group {
            children [
              DEF LEFT_1_BARS Pose {
                children [
                  DEF BARS Shape {
                    appearance PBRAppearance {
                      baseColorMap ImageTexture {
                        url [
                          "https://raw.githubusercontent.com/cyberbotics/webots/R2023b/projects/appearances/protos/textures/brushed_aluminium/brushed_aluminium_base_color.jpg"
                        ]
                      }
                      roughnessMap ImageTexture {
                        url [
                          "https://raw.githubusercontent.com/cyberbotics/webots/R2023b/projects/appearances/protos/textures/brushed_aluminium/brushed_aluminium_roughness.jpg"
                        ]
                      }
                      normalMap ImageTexture {
                        url [
                          "https://raw.githubusercontent.com/cyberbotics/webots/R2023b/projects/appearances/protos/textures/brushed_aluminium/brushed_aluminium_normal.jpg"
                        ]
                      }
                      textureTransform TextureTransform {
                        scale 3 2
                      }
                    }
                    geometry Mesh {
                      url [
                        "./turtleBot3Waffle_mesh/waffle_bars.obj"
                      ]
                    }
                  }
                ]
              }
              DEF LEFT_2_BARS Pose {
                translation -0.13 0 0
                children [
                  USE BARS
                ]
              }
              DEF RIGHT_1_BARS Pose {
                translation 0 -0.128 0
                children [
                  USE BARS
                ]
              }
              DEF RIGHT_2_BARS Pose {
                translation -0.128 -0.128 0
                children [
                  USE BARS
                ]
              }
            ]
          }
        ]
      }
      Accelerometer {
        translation -0.032 0 0.078
      }
      Gyro {
        translation -0.032 0 0.078
      }
      Compass {
        translation -0.032 0 0.078
      }
      DEF TURTLEBOT_CAMERA_LEFT Camera {
        # translation -0.225 -0.035 0.118
        # translation -0.225 -0.035 0.07  # On third plate
        translation -0.225 -0.035 0.05    # On second plate
        rotation IS camera_rotation
        children [
          DEF TURTLEBOT_CAMERA_MESH_POSE Pose {
            # translation 0.0 0.00150016 -0.02
            translation 0.0 0.00150016 -0.0
            rotation 3.3905113482557537e-09 0.70710528118436 0.707108281185553 3.14159
            children [
              DEF TURTLEBOT_CAMERA_SHPAE Shape {
                appearance PBRAppearance {
                  baseColor 0 0.3 0.5
                  roughness 0.4
                  metalness 0
                }
                geometry IndexedFaceSet {
                  coord Coordinate {
                    point [
                      -0.0001755 0.003 -0.003, -0.0024755 -0.003 -0.003, -0.0024755 0 -0.003, -0.0024755 0.003 -0.003, -2.55e-05 0.0035 -0.003, -2.55e-05 -0.003 -0.003, 0.0004273 0.0057498 -0.0030001, -0.0001755 0.0035 -0.003, 0.0005572 0.0056748 -0.0030001, 0.0020747 0.0073972 -0.0030001, 0.0021496 0.0072673 -0.0030001, 0.0043244 0.008 -0.0030001, 0.0043244 0.00785 -0.0030001, 0.0075744 0.008 -0.003, 0.0075744 0.0095 -0.0030001, 0.0115744 0.0095 -0.003, 0.0115744 0.008 -0.0029999, 0.0128244 0.008 -0.0029999, 0.0128244 0.00785 -0.0029999, -2.56e-05 -0.003 0.003, -0.0001756 0.0035 0.003, -0.0001756 0.003 0.003, -0.0024756 0.003 0.003, -0.0024756 0 0.003, -0.0024756 -0.003 0.003, -2.56e-05 0.0035 0.003, 0.0004272 0.0057498 0.0029999, 0.0005571 0.0056748 0.0029999, 0.0020746 0.0073972 0.0029999, 0.0021496 0.0072673 0.0029999, 0.0043244 0.00785 0.0029999, 0.0043244 0.008 0.0029999, 0.0115743 0.0095002 0.003, 0.0075744 0.0095001 0.0029999, 0.0115743 0.0080002 0.0030001, 0.0075744 0.0080001 0.003, 0.0128243 0.0078502 0.0030001, 0.0128243 0.0080002 0.0030001, -0.0024755 -0.003 0, -0.0024755 -0.0025982 -0.0014997, -0.0024756 -0.0025982 0.0014997, -0.0024756 -0.0015 0.002598, -0.0024755 -0.0015001 -0.002598, -0.0024756 0.0025982 0.0014997, -0.0024756 0.0015001 0.002598, -0.0024756 0.003 0, -0.0024755 0.0025982 -0.0014997, -0.0024755 0.0015 -0.002598, -0.0037756 0.0021213 0.0021212, -0.0037756 0.003 0, -0.0037755 0.0021213 -0.0021213, -0.0037755 0.002 -0.0015, -0.0037755 0.0015 -0.002, -0.0037755 0 -0.003, -0.0037756 0.002 0.0015, -0.0037756 0.0015 0.002, -0.0037756 0 0.003, -0.0037755 -0.0015 -0.002, -0.0037756 -0.0015 0.002, -0.0037755 -0.0021213 -0.0021213, -0.0037756 -0.002 0.0015, -0.0037755 -0.002 -0.0015, -0.0037756 -0.0021213 0.0021212, -0.0037755 -0.003 0, -0.0037755 0.0010606 -0.0025607, -0.0037755 0.0025606 -0.0010607, -0.0037756 0.0025606 0.0010606, -0.0037756 0.0010606 0.0025606, -0.0037756 -0.0010606 0.0025606, -0.0037756 -0.0025606 0.0010606, -0.0037755 -0.0025606 -0.0010607, -0.0037755 -0.0010607 -0.0025607, -0.0041756 -0.002 0.0015, -0.0041756 -0.0015 0.002, -0.0041755 -0.002 -0.0015, -0.0041755 -0.0015 -0.002, -0.0041756 0.0015 0.002, -0.0041756 0.0002451 0, -0.0041756 0.0001227 0.0002119, -0.0041756 -0.0001227 0.0002119, -0.0041756 -0.0002451 0, -0.0041756 -0.0001227 -0.000212, -0.0041756 0.0001227 -0.000212, -0.0041755 0.0015 -0.002, -0.0041756 0.002 0.0014999, -0.0041756 0.002 -0.0015001
                    ]
                  }
                  coordIndex [
                    33, 14, 35, -1, 13, 35, 14, -1, 15, 32, 16, -1, 34, 16, 32, -1, 14, 33, 15, -1, 32, 15, 33, -1, 72, 74, 60, -1, 61, 60, 74, -1, 74, 75, 61, -1, 57, 61, 75, -1, 75, 83, 57, -1, 52, 57, 83, -1, 83, 85, 52, -1, 51, 52, 85, -1, 85, 84, 51, -1, 54, 51, 84, -1, 84, 76, 54, -1, 55, 54, 76, -1, 76, 73, 55, -1, 58, 55, 73, -1, 73, 72, 58, -1, 60, 58, 72, -1, 72, 73, 74, -1, 75, 74, 73, -1, 76, 77, 78, -1, 76, 78, 79, -1, 79, 80, 75, -1, 79, 75, 73, -1, 73, 76, 79, -1, 75, 80, 81, -1, 75, 81, 82, -1, 82, 77, 76, -1, 82, 76, 83, -1, 83, 75, 82, -1, 76, 84, 83, -1, 85, 83, 84, -1, 56, 68, 23, -1, 41, 23, 68, -1, 68, 62, 41, -1, 40, 41, 62, -1, 62, 69, 40, -1, 40, 69, 63, -1, 38, 40, 63, -1, 63, 70, 38, -1, 39, 38, 70, -1, 70, 59, 39, -1, 42, 39, 59, -1, 59, 71, 42, -1, 42, 71, 53, -1, 2, 42, 53, -1, 53, 64, 2, -1, 47, 2, 64, -1, 64, 50, 47, -1, 46, 47, 50, -1, 50, 65, 46, -1, 46, 65, 49, -1, 45, 46, 49, -1, 49, 66, 45, -1, 43, 45, 66, -1, 66, 48, 43, -1, 44, 43, 48, -1, 48, 67, 44, -1, 44, 67, 56, -1, 23, 44, 56, -1, 48, 49, 50, -1, 51, 48, 50, -1, 52, 51, 50, -1, 50, 53, 52, -1, 48, 51, 54, -1, 48, 54, 55, -1, 56, 48, 55, -1, 57, 52, 53, -1, 55, 58, 56, -1, 59, 60, 61, -1, 59, 61, 57, -1, 53, 59, 57, -1, 60, 59, 62, -1, 58, 60, 62, -1, 62, 56, 58, -1, 59, 63, 62, -1, 0, 45, 22, -1, 21, 0, 22, -1, 45, 0, 3, -1, 38, 39, 1, -1, 40, 38, 24, -1, 41, 40, 24, -1, 24, 23, 41, -1, 1, 39, 42, -1, 2, 1, 42, -1, 22, 43, 44, -1, 23, 22, 44, -1, 45, 43, 22, -1, 46, 45, 3, -1, 47, 46, 3, -1, 3, 2, 47, -1, 20, 26, 7, -1, 6, 7, 26, -1, 26, 28, 6, -1, 9, 6, 28, -1, 28, 31, 9, -1, 11, 9, 31, -1, 31, 35, 11, -1, 13, 11, 35, -1, 34, 37, 16, -1, 17, 16, 37, -1, 36, 18, 37, -1, 17, 37, 18, -1, 36, 30, 18, -1, 12, 18, 30, -1, 4, 8, 25, -1, 27, 25, 8, -1, 8, 10, 27, -1, 29, 27, 10, -1, 10, 12, 29, -1, 30, 29, 12, -1, 25, 19, 4, -1, 5, 4, 19, -1, 24, 38, 19, -1, 19, 38, 1, -1, 5, 19, 1, -1, 20, 7, 21, -1, 0, 21, 7, -1, 19, 20, 21, -1, 19, 21, 22, -1, 19, 22, 23, -1, 24, 19, 23, -1, 20, 19, 25, -1, 26, 20, 25, -1, 25, 27, 26, -1, 28, 26, 27, -1, 27, 29, 28, -1, 28, 29, 30, -1, 31, 28, 30, -1, 32, 33, 34, -1, 34, 33, 35, -1, 36, 34, 35, -1, 36, 35, 31, -1, 30, 36, 31, -1, 37, 34, 36, -1, 0, 1, 2, -1, 3, 0, 2, -1, 0, 4, 5, -1, 1, 0, 5, -1, 4, 0, 6, -1, 6, 0, 7, -1, 8, 4, 6, -1, 6, 9, 8, -1, 10, 8, 9, -1, 9, 11, 10, -1, 12, 10, 11, -1, 11, 13, 12, -1, 14, 15, 13, -1, 13, 15, 16, -1, 12, 13, 16, -1, 12, 16, 17, -1, 18, 12, 17, -1
                  ]
                  creaseAngle 0.785398
                }
              }
            ]
          }
        ]
        name "camera_left"
        fieldOfView IS camera_fieldOfView
        width IS camera_width
        height IS camera_height
        near 0.0055
        antiAliasing IS camera_antiAliasing
        motionBlur IS camera_motionBlur
        noise IS camera_noise
        zoom Zoom {
        }
      }
      DEF TURTLEBOT_CAMERA_RIGHT Camera {
        # translation -0.225 -0.093 0.118
        # translation -0.225 -0.093 0.07  # On third plate
        translation -0.225 -0.093 0.05    # On second plate
        rotation IS camera_rotation
        children [
          USE TURTLEBOT_CAMERA_MESH_POSE
        ]
        name "camera_right"
        fieldOfView IS camera_fieldOfView
        width IS camera_width
        height IS camera_height
        near 0.0055
        antiAliasing IS camera_antiAliasing
        motionBlur IS camera_motionBlur
        noise IS camera_noise
        zoom Zoom {
        }
      }
      DEF TURTLEBOT_RECEIVER Receiver {
        channel IS receiver_channel
      }
      DEF TURTLEBOT_EMITTER Emitter {
        channel IS emitter_channel
      }
      DEF ARM_SLOT Group {
        children [
          Pose {
            children IS arm_slot
          }
        ]
      }
      Pen {
        translation 0 -0.06 0.001
        children [
          Pose {
            translation 0 0 0.07
            children [
              Shape {
                appearance PBRAppearance {
                  baseColor 1 0.692371 0
                  roughness 0.3707939685999999
                  metalness 0
                }
                geometry Cylinder {
                  height 0.14
                  radius 0.004
                }
              }
            ]
          }
        ]
        name "pen"
        leadSize 0.002
      }
    ]
    name IS name
    boundingObject Group {
      children [
        Pose {
          translation -0.095 -0.064 0.065
          children [
            Box {
              size 0.226 0.267 0.1
            }
          ]
        }
        Pose {
          translation -0.096 -0.064 0.06
          children [
            Box {
              size 0.265 0.215 0.1
            }
          ]
        }
      ]
    }
    physics Physics {
      density -1
      mass 1.825735
      centerOfMass [
        -0.035 0 0.03
      ]
    }
  }
}
