<?xml version="1.0"?>
<robot name="/home/jordenhuang/webots_ros2/src/my_package/resource/MyCobot280Pi.urdf" xmlns:xacro="http://ros.org/wiki/xacro">
  <link name="base_link">
    <visual>
      <origin xyz="0 0 -0.01" rpy="0 0 0"/>
      <geometry>
        <box size="0.1 0.1 0.08"/>
      </geometry>
    </visual>
    <collision>
      <origin xyz="0 0 -0.01" rpy="0 0 0"/>
      <geometry>
        <box size="0.1 0.1 0.08"/>
      </geometry>
    </collision>
  </link>
  <link name="base">
    <visual>
      <origin xyz="0 0 0.105" rpy="0 0 0"/>
      <geometry>
        <cylinder radius="0.025" length="0.05"/>
      </geometry>
    </visual>
    <collision>
      <origin xyz="0 0 0.105" rpy="0 0 0"/>
      <geometry>
        <cylinder radius="0.025" length="0.05"/>
      </geometry>
    </collision>
  </link>
  <joint name="base_link_base_joint" type="fixed">
    <parent link="base_link"/>
    <child link="base"/>
    <origin xyz="0 0 -0.05" rpy="0 0 0"/>
  </joint>
  <joint name="joint0_rotational_motor" type="revolute">
    <parent link="base"/>
    <child link="joint0"/>
    <axis xyz="-0.000001 -0.000002 1"/>
    <limit effort="1000" lower="-2.93217" upper="2.93217" velocity="10"/>
    <origin xyz="0 0 0.08" rpy="-0.000002 0.000001 -1.570802"/>
  </joint>
  <link name="joint0">
    <visual>
      <origin xyz="0.030001 0 0.059979" rpy="3.141593 1.570793 3.141593"/>
      <geometry>
        <cylinder radius="0.025" length="0.03"/>
      </geometry>
    </visual>
    <collision>
      <origin xyz="0.030001 0 0.059979" rpy="3.141593 1.570793 3.141593"/>
      <geometry>
        <cylinder radius="0.025" length="0.03"/>
      </geometry>
    </collision>
  </link>
  <joint name="joint1_rotational_motor" type="revolute">
    <parent link="joint0"/>
    <child link="join1"/>
    <axis xyz="1 0 0"/>
    <limit effort="1000" lower="-2.35619" upper="2.35619" velocity="10"/>
    <origin xyz="0.03 0 0.059979" rpy="0 0 0"/>
  </joint>
  <link name="join1">
    <visual>
      <origin xyz="0.031 0 0.06" rpy="0 0 0"/>
      <geometry>
        <cylinder radius="0.0225" length="0.07"/>
      </geometry>
    </visual>
    <collision>
      <origin xyz="0.031 0 0.06" rpy="0 0 0"/>
      <geometry>
        <cylinder radius="0.0225" length="0.07"/>
      </geometry>
    </collision>
    <visual>
      <origin xyz="0 0 0.11" rpy="-1.570799 -0.000002 -1.570792"/>
      <geometry>
        <cylinder radius="0.022" length="0.03"/>
      </geometry>
    </visual>
    <collision>
      <origin xyz="0 0 0.11" rpy="-1.570799 -0.000002 -1.570792"/>
      <geometry>
        <cylinder radius="0.022" length="0.03"/>
      </geometry>
    </collision>
  </link>
  <joint name="joint2_rotational_motor" type="revolute">
    <parent link="join1"/>
    <child link="joint2"/>
    <axis xyz="1 0 0"/>
    <limit effort="1000" lower="-2.61799" upper="2.61799" velocity="10"/>
    <origin xyz="0 0 0.1104" rpy="0 0 0"/>
  </joint>
  <link name="joint2">
    <visual>
      <origin xyz="-0.033 0 0.05" rpy="0 0 0.2618"/>
      <geometry>
        <cylinder radius="0.022" length="0.075"/>
      </geometry>
    </visual>
    <collision>
      <origin xyz="-0.033 0 0.05" rpy="0 0 0.2618"/>
      <geometry>
        <cylinder radius="0.022" length="0.075"/>
      </geometry>
    </collision>
    <visual>
      <origin xyz="0 0 0.096" rpy="0 -1.570795 0"/>
      <geometry>
        <cylinder radius="0.02" length="0.05"/>
      </geometry>
    </visual>
    <collision>
      <origin xyz="0 0 0.096" rpy="0 -1.570795 0"/>
      <geometry>
        <cylinder radius="0.02" length="0.05"/>
      </geometry>
    </collision>
  </link>
  <joint name="joint3_rotational_motor" type="revolute">
    <parent link="joint2"/>
    <child link="joint3"/>
    <axis xyz="1 0.000021 -0.000006"/>
    <limit effort="1000" lower="-2.53073" upper="2.53073" velocity="10"/>
    <origin xyz="-0.0005 0 0.0966" rpy="0 -0.000006 -0.000021"/>
  </joint>
  <link name="joint3">
    <visual>
      <origin xyz="0.033001 -0.000019 0.034934" rpy="0 0 0"/>
      <geometry>
        <cylinder radius="0.02" length="0.035"/>
      </geometry>
    </visual>
    <collision>
      <origin xyz="0.033001 -0.000019 0.034934" rpy="0 0 0"/>
      <geometry>
        <cylinder radius="0.02" length="0.035"/>
      </geometry>
    </collision>
  </link>
  <joint name="joint4_rotational_motor" type="revolute">
    <parent link="joint3"/>
    <child link="joint4"/>
    <axis xyz="0 0 1"/>
    <limit effort="1000" lower="-2.87979" upper="2.87979" velocity="10"/>
    <origin xyz="0.033701 -0.000019 0.033934" rpy="0 0 0"/>
  </joint>
  <link name="joint4">
    <visual>
      <origin xyz="0 0.005 0.038" rpy="-1.570795 0 0"/>
      <geometry>
        <cylinder radius="0.02" length="0.05"/>
      </geometry>
    </visual>
    <collision>
      <origin xyz="0 0.005 0.038" rpy="-1.570795 0 0"/>
      <geometry>
        <cylinder radius="0.02" length="0.05"/>
      </geometry>
    </collision>
  </link>
  <joint name="joint5_rotational_motor" type="revolute">
    <parent link="joint4"/>
    <child link="joint5"/>
    <axis xyz="0 0.000001 1"/>
    <limit effort="1000" lower="-3.14159" upper="3.14159" velocity="10"/>
    <origin xyz="-0.0001 0.0346 0.038" rpy="-1.570795 0 0"/>
  </joint>
  <link name="joint5">
    <visual>
      <origin xyz="0 0 0.007" rpy="0 0 0"/>
      <geometry>
        <cylinder radius="0.02" length="0.013"/>
      </geometry>
    </visual>
    <collision>
      <origin xyz="0 0 0.007" rpy="0 0 0"/>
      <geometry>
        <cylinder radius="0.02" length="0.013"/>
      </geometry>
    </collision>
  </link>
</robot>
